# Exception rise in this code 
# n= 10
# d = 0
# result = n/d
# print(result)


# handle exception
# try:
#     nu = 10
#     de = 0
#     result = nu/de
#     print(result)
# except:                                         # handle exception
#     print("Error: Denominator cannot be 0.")        


# Any task necessary to excecute then use finally
# try:
#     nu= 10
#     de = 0

#     result = nu/de

#     print(result)
# except:
#     print("Error: Denominator cannot be 0.")        
    
# finally:                                        #finally block it execute always
#     print("This is finally block.")




# try with multiple except
# try:
#   print(x)
# except NameError:
#   print("Variable x is not defined")
# except:
#   print("problem...")